<?xml version="1.0"?>

<robot name="wx250s" xmlns:xacro="http://ros.org/wiki/xacro">

    <xacro:macro name="gripper_prop" params="arm_prefix">

        <link name="${arm_prefix}/gripper_prop_link">
            <visual>
                <origin xyz="-0.0685 0 0" rpy="0 0 ${pi/2}" />
                <geometry>
                    <mesh filename="package://doudou_description/meshes/wx250s_meshes/wx250s_8_gripper_prop.stl" scale="0.001 0.001 0.001"/>
                </geometry>
                <material name="interbotix_black"/>
            </visual>
            <collision>
                <origin xyz="-0.0685 0 0" rpy="0 0 ${pi/2}" />
                <geometry>
                    <mesh filename="package://doudou_description/meshes/wx250s_meshes/wx250s_8_gripper_prop.stl" scale="0.001 0.001 0.001"/>
                </geometry>
            </collision>
            <inertial>
                <origin xyz="0.0008460000 -0.0000016817 0.0000420000" rpy="0 0 ${pi/2}" />
                <mass value="0.00434" />
                <inertia ixx="0.0000005923" iyy="0.0000011156" izz="0.0000005743" ixy="0.0000000000" ixz="0.0000003195" iyz="-0.0000000004" />
            </inertial>
        </link>

        <joint name="${arm_prefix}/gripper_joint" type="continuous">
            <axis xyz="1 0 0"/>
            <limit effort="1" velocity="${pi}"/>
            <origin rpy="0 0 0" xyz="0.0055 0 0"/>
            <parent link="${arm_prefix}/ee_arm_link"/>
            <child link="${arm_prefix}/gripper_prop_link"/>
            <dynamics friction="0.1"/>
        </joint>
        
        <transmission name="${arm_prefix}/trans_gripper">
            <type>transmission_interface/SimpleTransmission</type>
            <joint name="${arm_prefix}/gripper_joint">
                <hardwareInterface>hardware_interface/EffortJointInterface</hardwareInterface>
            </joint>
            <actuator name="${arm_prefix}/gripper_motor">
                <mechanicalReduction>1</mechanicalReduction>
            </actuator>
        </transmission>

    </xacro:macro>

</robot>