<?xml version="1.0"?>

<robot name="wx250s" xmlns:xacro="http://ros.org/wiki/xacro">

    <xacro:macro name="gripper_left_finger" params="arm_prefix">

        <link name="${arm_prefix}/left_finger_link">
            <visual>
                <origin xyz="0 0.005 0" rpy="${pi} ${pi} 0" />
                <geometry>
                    <mesh filename="package://doudou_description/meshes/wx250s_meshes/wx250s_10_gripper_finger.stl" scale="0.001 0.001 0.001"/>
                </geometry>
                <material name="interbotix_black"/>
            </visual>
            <collision>
                <origin xyz="0 0.005 0" rpy="${pi} ${pi} 0" />
                <geometry>
                    <mesh filename="package://doudou_description/meshes/wx250s_meshes/wx250s_10_gripper_finger.stl" scale="0.001 0.001 0.001"/>
                </geometry>
            </collision>
            <inertial>
                <origin xyz="0.0138160000 0.0000000000 0.0000000000" rpy="${pi} ${pi} ${pi/2}" />
                <mass value="0.016246" />
                <inertia ixx="0.0000047310" iyy="0.0000015506" izz="0.0000037467" ixy="-0.0000004560" ixz="0.0000000000" iyz="0.0000000000" />
            </inertial>
        </link>

        <joint name="${arm_prefix}/left_finger_joint" type="prismatic">
            <axis xyz="0 1 0"/>
            <limit effort="5" lower="0.015" upper="0.037" velocity="1"/>
            <origin xyz="0 0 0" rpy="0 0 0" />
            <parent link="${arm_prefix}/fingers_link"/>
            <child link="${arm_prefix}/left_finger_link"/>
            <dynamics friction="0.1"/>
        </joint>
    
        <transmission name="${arm_prefix}/trans_left_finger">
            <type>transmission_interface/SimpleTransmission</type>
            <joint name="${arm_prefix}/left_finger_joint">
                <hardwareInterface>hardware_interface/EffortJointInterface</hardwareInterface>
            </joint>
            <actuator name="${arm_prefix}/left_finger_motor">
                <mechanicalReduction>1</mechanicalReduction>
            </actuator>
        </transmission>

    </xacro:macro>

</robot>