<?xml version="1.0"?>

<robot name="tracer" xmlns:xacro="http://ros.org/wiki/xacro">
    <xacro:include filename="$(find doudou_description)/urdf/urdf_tracer/rl_castor.xacro" />
    
    <xacro:macro name="rl_wheel" params="wheel_prefix *joint_pose">
        <link name="tracer/${wheel_prefix}_wheel_link">
            <visual>
                <geometry>
                    <mesh filename="package://doudou_description/meshes/tracer_meshes/castor.dae" />
                </geometry>
            </visual>
            <collision>
                <origin xyz="0 0 0" rpy="0 0 0" />
                <geometry>
                    <mesh filename="package://doudou_description/meshes/tracer_meshes/castor.dae" />
                </geometry>
            </collision>
            <inertial>
                <mass value="1" />
                <origin xyz="0 0 0" />
                <inertia ixx="0.3131" ixy="0" ixz="0" iyy="0.3131" iyz="0" izz="0.1361" />
            </inertial>   
        </link>

        <joint name="tracer/${wheel_prefix}_wheel" type="continuous">
            <parent link="tracer/rl_castor_link"/>
            <child link="tracer/${wheel_prefix}_wheel_link"/>
            <dynamics damping="0.0" friction="0.0"/>
            <xacro:insert_block name="joint_pose"/>
            <axis xyz="0 0 1" rpy="0 0 0" />
        </joint>

    </xacro:macro>

</robot>