<?xml version="1.0"?>

<robot name="tracer" xmlns:xacro="http://ros.org/wiki/xacro">

    <xacro:macro name="tracer_wheel_1" params="wheel_prefix *joint_pose">
        <link name="tracer/${wheel_prefix}_wheel_link">
            <visual>
                <origin xyz="0 0 0" rpy="0 0 0" />
                <geometry>
                    <mesh filename="package://doudou_description/meshes/tracer_meshes/tracer_wheel.dae" />
                </geometry>
            </visual>
            <collision>
                <origin xyz="0 0 0" rpy="0 0 0" />
                <geometry>
                	<mesh filename="package://doudou_description/meshes/tracer_meshes/tracer_wheel.dae" />
                </geometry>
            </collision>
            <inertial>
                <mass value="6" />
                <origin xyz="0 0 0" />
                <inertia ixx="0.7171" ixy="0" ixz="0" iyy="0.1361" iyz="0" izz="0.7171" />
            </inertial>
        </link>

		<joint name="tracer/${wheel_prefix}_wheel" type="continuous">
            <parent link="tracer/base_link"/>
            <child link="tracer/${wheel_prefix}_wheel_link"/>
            <xacro:insert_block name="joint_pose"/>
            <axis xyz="0 1 0" rpy="0 0 0" />
        </joint>

    </xacro:macro>

</robot>