<?xml version="1.0"?>

<robot name="wx250s" xmlns:xacro="http://ros.org/wiki/xacro">

    <xacro:macro name="arm_shoulder" params="arm_prefix">

        <link name="${arm_prefix}/shoulder_link">
            <visual>
                <origin xyz="0 0 -0.003" rpy="0 0 ${pi/2}" />
                <geometry>
                    <mesh filename="package://doudou_description/meshes/wx250s_meshes/wx250s_2_shoulder.stl" scale="0.001 0.001 0.001"/>
                </geometry>
                <material name="interbotix_black"/>
            </visual>
            <collision>
                <origin xyz="0 0 -0.003" rpy="0 0 ${pi/2}" />
                <geometry>
                    <mesh filename="package://doudou_description/meshes/wx250s_meshes/wx250s_2_shoulder.stl" scale="0.001 0.001 0.001"/>
                </geometry>
            </collision>
            <inertial>
                <origin xyz="0.0000223482 0.0000414609 0.0066287000" rpy="0 0 ${pi/2}" />
                <mass value="0.480879" />
                <inertia ixx="0.0003790000" iyy="0.0005557000" izz="0.0005889000" ixy="0.0000000022" ixz="-0.0000003561" iyz="0.0000012245" />
            </inertial>
        </link>
    
        <joint name="${arm_prefix}/waist_joint" type="revolute">
            <axis xyz="0 0 1"/>
            <limit effort="10" lower="${-pi + pi_offset}" upper="${pi - pi_offset}" velocity="${pi}"/>
            <origin xyz="0 0 0.072" rpy="0 0 0" />
            <parent link="${arm_prefix}/base_link"/>
            <child link="${arm_prefix}/shoulder_link"/>
            <dynamics friction="0.1"/>
        </joint>
    
        <transmission name="${arm_prefix}/trans_waist">
            <type>transmission_interface/SimpleTransmission</type>
            <joint name="${arm_prefix}/waist_joint">
                <hardwareInterface>hardware_interface/EffortJointInterface</hardwareInterface>
            </joint>
            <actuator name="${arm_prefix}/waist_motor">
                <mechanicalReduction>1</mechanicalReduction>
            </actuator>
        </transmission>
    
    </xacro:macro>

</robot>