<?xml version="1.0"?>

<robot name="wx250s" xmlns:xacro="http://ros.org/wiki/xacro">

    <xacro:macro name="arm_upper_forearm" params="arm_prefix">

        <link name="${arm_prefix}/upper_forearm_link">
            <visual>
                <origin xyz="0 0 0" rpy="0 0 0" />
                <geometry>
                    <mesh filename="package://doudou_description/meshes/wx250s_meshes/wx250s_4_upper_forearm.stl" scale="0.001 0.001 0.001"/>
                </geometry>
                <material name="interbotix_black"/>
            </visual>
            <collision>
                <origin xyz="0 0 0" rpy="0 0 0" />
                <geometry>
                    <mesh filename="package://doudou_description/meshes/wx250s_meshes/wx250s_4_upper_forearm.stl" scale="0.001 0.001 0.001"/>
                </geometry>
            </collision>
            <inertial>
                <origin xyz="0.1079630000 0.0001158760 0" rpy="0 0 0" />
                <mass value="0.234589" />
                <inertia ixx="0.0000397100" iyy="0.0008878000" izz="0.0008880000" ixy="0.0000023528" ixz="0" iyz="0" />
            </inertial>
        </link>
    
        <joint name="${arm_prefix}/elbow_joint" type="revolute">
            <axis xyz="0 1 0"/>
            <limit effort="15" lower="${radians(-123)}" upper="${radians(92)}" velocity="${pi}"/>
            <origin xyz="0.04975 0 0.25" rpy="0 0 0" />
            <parent link="${arm_prefix}/upper_arm_link"/>
            <child link="${arm_prefix}/upper_forearm_link"/>
            <dynamics friction="0.1"/>
        </joint>
        
        <transmission name="${arm_prefix}/trans_elbow">
            <type>transmission_interface/SimpleTransmission</type>
            <joint name="${arm_prefix}/elbow_joint">
                <hardwareInterface>hardware_interface/EffortJointInterface</hardwareInterface>
            </joint>
            <actuator name="${arm_prefix}/elbow_motor">
                <mechanicalReduction>1</mechanicalReduction>
            </actuator>
        </transmission>

    </xacro:macro>
     
</robot>
