<?xml version="1.0"?>

<robot name="wx250s" xmlns:xacro="http://ros.org/wiki/xacro">

    <xacro:macro name="arm_lower_forearm" params="arm_prefix">

        <link name="${arm_prefix}/lower_forearm_link">
            <visual>
                <origin xyz="0 0 0" rpy="${pi} 0 0" />
                <geometry>
                    <mesh filename="package://doudou_description/meshes/wx250s_meshes/wx250s_5_lower_forearm.stl" scale="0.001 0.001 0.001"/>
                </geometry>
                <material name="interbotix_black"/>
            </visual>
            <collision>
                <origin xyz="0 0 0" rpy="${pi} 0 0" />
                <geometry>
                    <mesh filename="package://doudou_description/meshes/wx250s_meshes/wx250s_5_lower_forearm.stl" scale="0.001 0.001 0.001"/>
                </geometry>
            </collision>
            <inertial>
                <origin xyz="0.0374395000 0.0052225200 0" rpy="${pi} 0 0" />
                <mass value="0.220991" />
                <inertia ixx="0.0000636900" iyy="0.0001677000" izz="0.0001834000" ixy="-0.0000229200" ixz="0" iyz="0" />
            </inertial>
        </link>
        
        <joint name="${arm_prefix}/forearm_roll_joint" type="revolute">
            <axis xyz="1 0 0"/>
            <limit effort="2" lower="${-pi + pi_offset}" upper="${pi - pi_offset}" velocity="${pi}"/>
            <origin rpy="0 0 0" xyz="0.175 0 0"/>
            <parent link="${arm_prefix}/upper_forearm_link"/>
            <child link="${arm_prefix}/lower_forearm_link"/>
            <dynamics friction="0.1"/>
        </joint>
        
        <transmission name="${arm_prefix}/trans_forearm_roll">
            <type>transmission_interface/SimpleTransmission</type>
            <joint name="${arm_prefix}/forearm_roll_joint">
                <hardwareInterface>hardware_interface/EffortJointInterface</hardwareInterface>
            </joint>
            <actuator name="${arm_prefix}/forearm_roll_motor">
                <mechanicalReduction>1</mechanicalReduction>
            </actuator>
        </transmission>

    </xacro:macro>
    
</robot>