<?xml version="1.0"?>

<robot name="wx250s" xmlns:xacro="http://ros.org/wiki/xacro">

    <xacro:macro name="arm_gripper" params="arm_prefix">

        <link name="${arm_prefix}/gripper_link">
            <visual>
                <origin xyz="-0.02 0 0" rpy="0 0 ${pi/2}" />
                <geometry>
                    <mesh filename="package://doudou_description/meshes/wx250s_meshes/wx250s_7_gripper.stl" scale="0.001 0.001 0.001"/>
                </geometry>
                <material name="interbotix_black"/>
            </visual>
            <collision>
                <origin xyz="-0.02 0 0" rpy="0 0 ${pi/2}" />
                <geometry>
                    <mesh filename="package://doudou_description/meshes/wx250s_meshes/wx250s_7_gripper.stl" scale="0.001 0.001 0.001"/>
                </geometry>
            </collision>
            <inertial>
                <origin xyz="0.0216310000 0.0000002516 0.0114100000" rpy="0 0 ${pi/2}" />
                <mass value="0.072885" />
                <inertia ixx="0.0000253700" iyy="0.0000183600" izz="0.0000167400" ixy="0.0000000000" ixz="0.0000000000" iyz="0.0000004340" />
            </inertial>
        </link>

        <joint name="${arm_prefix}/wrist_rotate_joint" type="revolute">
            <axis xyz="1 0 0"/>
            <limit effort="1" lower="${-pi + pi_offset}" upper="${pi - pi_offset}" velocity="${pi}"/>
            <origin xyz="0.065 0 0" rpy="0 0 0" />
            <parent link="${arm_prefix}/wrist_link"/>
            <child link="${arm_prefix}/gripper_link"/>
            <dynamics friction="0.1"/>
        </joint>

        <transmission name="${arm_prefix}/trans_wrist_rotate">
            <type>transmission_interface/SimpleTransmission</type>
            <joint name="${arm_prefix}/wrist_rotate_joint">
                <hardwareInterface>hardware_interface/EffortJointInterface</hardwareInterface>
            </joint>
            <actuator name="${arm_prefix}/wrist_rotate_motor">
                <mechanicalReduction>1</mechanicalReduction>
            </actuator>
        </transmission>

    </xacro:macro>

</robot>