<?xml version="1.0"?>

<robot name="wx250s" xmlns:xacro="http://ros.org/wiki/xacro">

    <xacro:macro name="arm_upper_arm" params="arm_prefix">

        <link name="${arm_prefix}/upper_arm_link">
            <visual>
                <origin xyz="0 0 0" rpy="0 0 ${pi/2}" />
                    <geometry>
                        <mesh filename="package://doudou_description/meshes/wx250s_meshes/wx250s_3_upper_arm.stl" scale="0.001 0.001 0.001"/>
                    </geometry>
                    <material name="interbotix_black"/>
            </visual>
            <collision>
                    <origin xyz="0 0 0" rpy="0 0 ${pi/2}" />
                    <geometry>
                        <mesh filename="package://doudou_description/meshes/wx250s_meshes/wx250s_3_upper_arm.stl" scale="0.001 0.001 0.001"/>
                    </geometry>
            </collision>
            <inertial>
                    <origin xyz="0.0171605000 0.0000002725 0.1913230000" rpy="0 0 ${pi/2}" />
                    <mass value="0.430811" />
                    <inertia ixx="0.0034630000" iyy="0.0035870000" izz="0.0004566000" ixy="-0.0000000001" ixz="-0.0000000002" iyz="0.0004272000" />
            </inertial>
        </link>

        <joint name="${arm_prefix}/arm_shoulder_joint" type="revolute">
            <axis xyz="0 1 0"/>
            <limit effort="20" lower="${radians(-108)}" upper="${radians(114)}" velocity="${pi}"/>
            <origin xyz="0 0 0.03865" rpy="0 0 0" />
            <parent link="${arm_prefix}/shoulder_link"/>
            <child link="${arm_prefix}/upper_arm_link"/>
            <dynamics friction="0.1"/>
        </joint>

        <transmission name="${arm_prefix}/trans_shoulder">
            <type>transmission_interface/SimpleTransmission</type>
            <joint name="${arm_prefix}/arm_shoulder_joint">
                <hardwareInterface>hardware_interface/EffortJointInterface</hardwareInterface>
            </joint>
            <actuator name="${arm_prefix}/shoulder_motor">
                <mechanicalReduction>1</mechanicalReduction>
            </actuator>
        </transmission>

    </xacro:macro>

</robot>