<?xml version="1.0"?>

<robot name="wx250s" xmlns:xacro="http://ros.org/wiki/xacro">

    <xacro:macro name="arm_wrist" params="arm_prefix">

        <link name="${arm_prefix}/wrist_link">
            <visual>
                <origin xyz="0 0 0" rpy="0 0 ${pi/2}" />
                <geometry>
                    <mesh filename="package://doudou_description/meshes/wx250s_meshes/wx250s_6_wrist.stl" scale="0.001 0.001 0.001"/>
                </geometry>
                <material name="interbotix_black"/>
            </visual>
            <collision>
                <origin xyz="0 0 0" rpy="0 0 ${pi/2}" />
                <geometry>
                    <mesh filename="package://doudou_description/meshes/wx250s_meshes/wx250s_6_wrist.stl" scale="0.001 0.001 0.001"/>
                </geometry>
            </collision>
            <inertial>
                <origin xyz="0.0423600000 -0.0000106630 0.0105770000" rpy="0 0 ${pi/2}" />
                <mass value="0.084957" />
                <inertia ixx="0.0000308200" iyy="0.0000282200" izz="0.0000315200" ixy="0.0000000191" ixz="0.0000000023" iyz="0.0000025481" />
            </inertial>
        </link>
        
        <joint name="${arm_prefix}/wrist_angle_joint" type="revolute">
            <axis xyz="0 1 0"/>
            <limit effort="5" lower="${radians(-100)}" upper="${radians(123)}" velocity="${pi}"/>
            <origin xyz="0.075 0 0" rpy="0 0 0" />
            <parent link="${arm_prefix}/lower_forearm_link"/>
            <child link="${arm_prefix}/wrist_link"/>
            <dynamics friction="0.1"/>
        </joint>
        
        <transmission name="${arm_prefix}/trans_wrist_angle">
            <type>transmission_interface/SimpleTransmission</type>
            <joint name="${arm_prefix}/wrist_angle_joint">
                <hardwareInterface>hardware_interface/EffortJointInterface</hardwareInterface>
            </joint>
            <actuator name="${arm_prefix}/wrist_angle_motor">
                <mechanicalReduction>1</mechanicalReduction>
            </actuator>
        </transmission>

    </xacro:macro>

</robot>